Workbook

Sheet Index
B1: Bike Sharing Demand Analysis Project (Excel)
B3: NextHikes IT Solutions - Data analysis with Excel, VBA and automated reporting
B5: Business question | C5: How do time of day, weather, holidays and user type affect bike rentals, and what can be planned better?
B6: Data | C6: Three hourly files merged on instant: 1,000 records, 1 Jan - 14 Feb 2011 (mid-winter, one city system).
B7: Colour code | C7: Yellow cells = inputs you can change. Everything else is a formula.
B9: Sheet | C9: What it contains | D9: Project task
B10: Raw_D1 / Raw_D2 / Raw_D3 | C10: The three source files, untouched | D10: Task 2 - loading
B11: Lookups | C11: Code tables, regression and threshold parameters | D11: Task 3
B12: Clean_Data | C12: Merged table (INDEX/MATCH on instant), imputation, flags, derived columns, anomaly z-score | D12: Tasks 2, 3
B13: DQ_Log | C13: Row reconciliation, missing values, duplicates, range checks, issue log | D13: Task 2
B14: T1_Foundations | C14: Shortcuts, SUM/AVERAGE/COUNT, LEFT/MID/RIGHT/LEN, top 10, conditional formatting | D14: Task 1
B15: T3_Logic_Lookup | C15: IF / nested IF, VLOOKUP, INDEX-MATCH, record finder | D15: Task 3
B16: T4_Pivots | C16: Nine pivot-style summaries with calculated fields, pivot charts, heat map | D16: Task 4
B17: T4_Stats | C17: Descriptive statistics, CORREL matrix, COUNTIF/SUMIF/AVERAGEIF, STDEV | D17: Task 4
B18: Daily_Trend | C18: Daily totals, regression model, 7-day forecast (also FORECAST.ETS), residual anomalies | D18: Task 5
B19: Anomaly_Report | C19: Hourly anomalies (z-score by hour and day type) | D19: Task 5
B20: Dash_Calc | C20: Calculation layer for the dashboard | D20: Task 5
... B22: Insights | C22: Formula-driven findings and recommendations | D22: Deliverable
B24: Method notes
B25: Merge: dataset_1 and dataset_2 are joined on instant; dataset_3 (already complete) is appended. Clean_Data pulls every value with INDEX/MATCH, so changing a raw value updates everything.
B26: Missing atemp (11 hours) is imputed by regression on temp; atemp = 0 is genuine and kept. Hours with no rentals are absent in the source and are not invented.
B27: Pivot tables: the summaries are formula based so they always refresh. Native PivotTables and slicers are created by the VBA module Module_Pivots (see the VBA folder).
B28: Forecast: regression with trend and weekend effect, compared with Excel FORECAST.ETS. The last day (14 Feb, data stops at 07:00) is left out of the model.
B29: Limit of the data: 45 winter days, so seasonal and temperature conclusions are limited. Hourly patterns and weather effects are well supported.

Sheet Raw_D1
A1: instant | B1: dteday | C1: season | D1: yr | E1: mnth | F1: hr | G1: holiday | H1: weekday | I1: weathersit | J1: temp
A2: 1 | B2: 40544 | C2: 1 | D2: 0 | E2: 1 | F2: 0 | G2: FALSE | H2: 6 | I2: 1 | J2: 0.24
A3: 2 | B3: 40544 | C3: 1 | D3: 0 | E3: 1 | F3: 1 | G3: FALSE | H3: 6 | I3: 1 | J3: 0.22
A4: 3 | B4: 40544 | C4: 1 | D4: 0 | E4: 1 | F4: 2 | G4: FALSE | H4: 6 | I4: 1 | J4: 0.22
A5: 4 | B5: 40544 | C5: 1 | D5: 0 | E5: 1 | F5: 3 | G5: FALSE | H5: 6 | I5: 1 | J5: 0.24
A6: 5 | B6: 40544 | C6: 1 | D6: 0 | E6: 1 | F6: 4 | G6: FALSE | H6: 6 | I6: 1 | J6: 0.24
A7: 6 | B7: 40544 | C7: 1 | D7: 0 | E7: 1 | F7: 5 | G7: FALSE | H7: 6 | I7: 2 | J7: 0.24
A8: 7 | B8: 40544 | C8: 1 | D8: 0 | E8: 1 | F8: 6 | G8: FALSE | H8: 6 | I8: 1 | J8: 0.22
A9: 8 | B9: 40544 | C9: 1 | D9: 0 | E9: 1 | F9: 7 | G9: FALSE | H9: 6 | I9: 1 | J9: 0.2
A10: 9 | B10: 40544 | C10: 1 | D10: 0 | E10: 1 | F10: 8 | G10: FALSE | H10: 6 | I10: 1 | J10: 0.24
A11: 10 | B11: 40544 | C11: 1 | D11: 0 | E11: 1 | F11: 9 | G11: FALSE | H11: 6 | I11: 1 | J11: 0.32
A12: 11 | B12: 40544 | C12: 1 | D12: 0 | E12: 1 | F12: 10 | G12: FALSE | H12: 6 | I12: 1 | J12: 0.38
A13: 12 | B13: 40544 | C13: 1 | D13: 0 | E13: 1 | F13: 11 | G13: FALSE | H13: 6 | I13: 1 | J13: 0.36
... A611: 610 | B611: 40571 | C611: 1 | D611: 0 | E611: 1 | F611: 15 | G611: FALSE | H611: 5 | I611: 2 | J611: 0.2

Sheet Raw_D2
A1: Unnamed: 0 | B1: instant | C1: atemp | D1: hum | E1: windspeed | F1: casual | G1: registered | H1: cnt
A2: 0 | B2: 1 | C2: 0.2879 | D2: 0.81 | E2: 0 | F2: 3 | G2: 13 | H2: 16
A3: 1 | B3: 2 | C3: 0.2727 | D3: 0.8 | E3: 0 | F3: 8 | G3: 32 | H3: 40
A4: 2 | B4: 3 | C4: 0.2727 | D4: 0.8 | E4: 0 | F4: 5 | G4: 27 | H4: 32
A5: 3 | B5: 4 | C5: 0.2879 | D5: 0.75 | E5: 0 | F5: 3 | G5: 10 | H5: 13
A6: 4 | B6: 5 | C6: 0.2879 | D6: 0.75 | E6: 0 | F6: 0 | G6: 1 | H6: 1
A7: 5 | B7: 6 | C7: 0.2576 | D7: 0.75 | E7: 0.0896 | F7: 0 | G7: 1 | H7: 1
A8: 6 | B8: 7 | C8: 0.2727 | D8: 0.8 | E8: 0 | F8: 2 | G8: 0 | H8: 2
A9: 7 | B9: 8 | C9: 0.2576 | D9: 0.86 | E9: 0 | F9: 1 | G9: 2 | H9: 3
A10: 8 | B10: 9 | D10: 0.75 | E10: 0 | F10: 1 | G10: 7 | H10: 8
A11: 9 | B11: 10 | C11: 0.3485 | D11: 0.76 | E11: 0 | F11: 8 | G11: 6 | H11: 14
A12: 10 | B12: 11 | C12: 0.3939 | D12: 0.76 | E12: 0.2537 | F12: 12 | G12: 24 | H12: 36
A13: 11 | B13: 12 | C13: 0.3333 | D13: 0.81 | E13: 0.2836 | F13: 26 | G13: 30 | H13: 56
A14: 12 | B14: 13 | C14: 0.4242 | D14: 0.77 | E14: 0.2836 | F14: 29 | G14: 55 | H14: 84
A15: 13 | B15: 14 | C15: 0.4545 | D15: 0.72 | E15: 0.2985 | F15: 47 | G15: 47 | H15: 94
A16: 14 | B16: 15 | C16: 0.4545 | D16: 0.72 | E16: 0.2836 | F16: 35 | G16: 71 | H16: 106
A17: 15 | B17: 16 | C17: 0.4394 | D17: 0.77 | E17: 0.2985 | F17: 40 | G17: 70 | H17: 110
A18: 16 | B18: 17 | C18: 0.4242 | D18: 0.82 | E18: 0.2985 | F18: 41 | G18: 52 | H18: 93
A19: 17 | B19: 18 | D19: 0.82 | E19: 0.2836 | F19: 15 | G19: 52 | H19: 67
A20: 18 | B20: 19 | C20: 0.4242 | D20: 0.88 | E20: 0.2537 | F20: 9 | G20: 26 | H20: 35
A21: 19 | B21: 20 | C21: 0.4242 | D21: 0.88 | E21: 0.2537 | F21: 6 | G21: 31 | H21: 37
A22: 20 | B22: 21 | C22: 0.4091 | D22: 0.87 | E22: 0.2537 | F22: 11 | G22: 25 | H22: 36
A23: 21 | B23: 22 | C23: 0.4091 | D23: 0.87 | E23: 0.194 | F23: 3 | G23: 31 | H23: 34
A24: 22 | B24: 23 | C24: 0.4091 | D24: 0.94 | E24: 0.2239 | F24: 11 | G24: 17 | H24: 28
A25: 23 | B25: 24 | D25: 0.88 | E25: 0.2985 | F25: 15 | G25: 24 | H25: 39
A26: 24 | B26: 25 | C26: 0.4545 | D26: 0.88 | E26: 0.2985 | F26: 4 | G26: 13 | H26: 17
A27: 25 | B27: 26 | C27: 0.4394 | D27: 0.94 | E27: 0.2537 | F27: 1 | G27: 16 | H27: 17
A28: 26 | B28: 27 | C28: 0.4242 | D28: 1 | E28: 0.2836 | F28: 1 | G28: 8 | H28: 9
A29: 27 | B29: 28 | C29: 0.4545 | D29: 0.94 | E29: 0.194 | F29: 2 | G29: 4 | H29: 6
A30: 28 | B30: 29 | D30: 0.94 | E30: 0.194 | F30: 2 | G30: 1 | H30: 3
A31: 29 | B31: 30 | C31: 0.4242 | D31: 0.77 | E31: 0.2985 | F31: 0 | G31: 2 | H31: 2
A32: 30 | B32: 31 | C32: 0.4091 | D32: 0.76 | E32: 0.194 | F32: 0 | G32: 1 | H32: 1
A33: 31 | B33: 32 | C33: 0.4091 | D33: 0.71 | E33: 0.2239 | F33: 0 | G33: 8 | H33: 8
A34: 32 | B34: 33 | D34: 0.76 | E34: 0.2239 | F34: 1 | G34: 19 | H34: 20
A35: 33 | B35: 34 | C35: 0.3485 | D35: 0.81 | E35: 0.2239 | F35: 7 | G35: 46 | H35: 53
A36: 34 | B36: 35 | C36: 0.3333 | D36: 0.71 | E36: 0.2537 | F36: 16 | G36: 54 | H36: 70
A37: 35 | B37: 36 | C37: 0.3333 | D37: 0.66 | E37: 0.2985 | F37: 20 | G37: 73 | H37: 93
A38: 36 | B38: 37 | C38: 0.3485 | D38: 0.66 | E38: 0.1343 | F38: 11 | G38: 64 | H38: 75
A39: 37 | B39: 38 | D39: 0.76 | E39: 0.194 | F39: 4 | G39: 55 | H39: 59
A40: 38 | B40: 39 | C40: 0.3333 | D40: 0.81 | E40: 0.1642 | F40: 19 | G40: 55 | H40: 74
...

Sheet Raw_D3
A1: instant | B1: dteday | C1: season | D1: yr | E1: mnth | F1: hr | G1: holiday | H1: weekday | I1: weathersit | J1: temp | K1: atemp | L1: hum | M1: windspeed | N1: casual | O1: registered | P1: cnt
A2: 620 | B2: 40572 | C2: 1 | D2: 0 | E2: 1 | F2: 1 | G2: FALSE | H2: 6 | I2: 1 | J2: 0.22 | K2: 0.2273 | L2: 0.64 | M2: 0.194 | N2: 0 | O2: 20 | P2: 20
A3: 621 | B3: 40572 | C3: 1 | D3: 0 | E3: 1 | F3: 2 | G3: FALSE | H3: 6 | I3: 1 | J3: 0.22 | K3: 0.2273 | L3: 0.64 | M3: 0.1642 | N3: 0 | O3: 15 | P3: 15
A4: 622 | B4: 40572 | C4: 1 | D4: 0 | E4: 1 | F4: 3 | G4: FALSE | H4: 6 | I4: 1 | J4: 0.2 | K4: 0.2121 | L4: 0.64 | M4: 0.1343 | N4: 3 | O4: 5 | P4: 8
A5: 623 | B5: 40572 | C5: 1 | D5: 0 | E5: 1 | F5: 4 | G5: FALSE | H5: 6 | I5: 1 | J5: 0.16 | K5: 0.1818 | L5: 0.69 | M5: 0.1045 | N5: 1 | O5: 2 | P5: 3
A6: 624 | B6: 40572 | C6: 1 | D6: 0 | E6: 1 | F6: 6 | G6: FALSE | H6: 6 | I6: 1 | J6: 0.16 | K6: 0.1818 | L6: 0.64 | M6: 0.1343 | N6: 0 | O6: 2 | P6: 2
A7: 625 | B7: 40572 | C7: 1 | D7: 0 | E7: 1 | F7: 7 | G7: FALSE | H7: 6 | I7: 1 | J7: 0.16 | K7: 0.1818 | L7: 0.59 | M7: 0.1045 | N7: 1 | O7: 4 | P7: 5
A8: 626 | B8: 40572 | C8: 1 | D8: 0 | E8: 1 | F8: 8 | G8: FALSE | H8: 6 | I8: 1 | J8: 0.18 | K8: 0.197 | L8: 0.55 | M8: 0.1642 | N8: 3 | O8: 31 | P8: 34
A9: 627 | B9: 40572 | C9: 1 | D9: 0 | E9: 1 | F9: 9 | G9: FALSE | H9: 6 | I9: 1 | J9: 0.18 | K9: 0.2121 | L9: 0.59 | M9: 0.0896 | N9: 0 | O9: 34 | P9: 34
A10: 628 | B10: 40572 | C10: 1 | D10: 0 | E10: 1 | F10: 10 | G10: FALSE | H10: 6 | I10: 2 | J10: 0.18 | K10: 0.2121 | L10: 0.64 | M10: 0.1045 | N10: 4 | O10: 51 | P10: 55
A11: 629 | B11: 40572 | C11: 1 | D11: 0 | E11: 1 | F11: 11 | G11: FALSE | H11: 6 | I11: 2 | J11: 0.18 | K11: 0.197 | L11: 0.64 | M11: 0.1343 | N11: 4 | O11: 60 | P11: 64
A12: 630 | B12: 40572 | C12: 1 | D12: 0 | E12: 1 | F12: 12 | G12: FALSE | H12: 6 | I12: 2 | J12: 0.2 | K12: 0.197 | L12: 0.59 | M12: 0.194 | N12: 12 | O12: 66 | P12: 78
A13: 631 | B13: 40572 | C13: 1 | D13: 0 | E13: 1 | F13: 13 | G13: FALSE | H13: 6 | I13: 2 | J13: 0.22 | K13: 0.2273 | L13: 0.55 | M13: 0.1642 | N13: 9 | O13: 56 | P13: 65
... A391: 619 | B391: 40572 | C391: 1 | D391: 0 | E391: 1 | F391: 0 | G391: FALSE | H391: 6 | I391: 1 | J391: 0.22 | K391: 0.197 | L391: 0.64 | M391: 0.3582 | N391: 2 | O391: 26 | P391: 28

Sheet Lookups
A1: Lookup tables & model parameters
A2: Code tables used by VLOOKUP / INDEX-MATCH in Clean_Data. Parameters (yellow) can be changed and the whole workbook updates.
A3: weathersit | B3: weather_name | D3: season | E3: season_name | G3: hour_from | H3: time_block | J3: Parameter | K3: Value | M3: weekday | N3: day
A4: 1 | B4: Clear | D4: 1 | E4: Winter | G4: 0 | H4: Night (00-05) | J4: atemp ~ temp : slope | K4: =SLOPE(Clean_Data!$K$2:$K$1001,Clean_Data!$J$2:$J$1001) -> 0.91849744 | M4: 0 | N4: Sun
A5: 2 | B5: Mist/Cloudy | D5: 2 | E5: Spring | G5: 6 | H5: Morning Peak (06-09) | J5: atemp ~ temp : intercept | K5: =INTERCEPT(Clean_Data!$K$2:$K$1001,Clean_Data!$J$2:$J$1001) -> 0.023930544 | M5: 1 | N5: Mon
A6: 3 | B6: Light Rain/Snow | D6: 3 | E6: Summer | G6: 10 | H6: Midday (10-15) | J6: Hourly anomaly threshold (|z|) | K6: 3 | M6: 2 | N6: Tue
A7: 4 | B7: Heavy Rain/Snow | D7: 4 | E7: Fall | G7: 16 | H7: Evening Peak (16-19) | J7: High-demand cut-off (75th pct of cnt) | K7: {=PERCENTILE(IF(Clean_Data!$V$2:$V$1001=1,Clean_Data!$P$2:$P$1001),0.75)} -> 83 | M7: 3 | N7: Wed
G8: 20 | H8: Late Evening (20-23) | J8: Low-demand cut-off (25th pct of cnt) | K8: {=PERCENTILE(IF(Clean_Data!$V$2:$V$1001=1,Clean_Data!$P$2:$P$1001),0.25)} -> 16 | M8: 4 | N8: Thu
J9: Rows used for regression | K9: =SUMPRODUCT(ISNUMBER(Clean_Data!$K$2:$K$1001)*ISNUMBER(Clean_Data!$J$2:$J$1001)) -> 989 | M9: 5 | N9: Fri
A10: Scaling used for real-world units (dataset documentation): temp x 41 = deg C, atemp x 50 = deg C, hum x 100 = %, windspeed x 67 = km/h. | J10: Rows loaded: dataset_1 | K10: =COUNT(Raw_D1!$A$2:$A$1001) -> 610 | M10: 6 | N10: Sat
A11: Note: season 1-4 = Winter, Spring, Summer, Fall; weekday 0 = Sunday; weathersit 1 = best, 4 = worst. | J11: Rows loaded: dataset_3 | K11: =COUNT(Raw_D3!$A$2:$A$1001) -> 390
J12: Daily anomaly threshold (|z|) | K12: 2

Sheet Clean_Data
A1: instant | B1: dteday | C1: season | D1: yr | E1: mnth | F1: hr | G1: holiday | H1: weekday | I1: weathersit | J1: temp | K1: atemp_raw | L1: hum | M1: windspeed | N1: casual | O1: registered | P1: cnt | Q1: source | R1: atemp | S1: atemp_status | T1: cnt_check | U1: dup_check | V1: include | W1: day_type | X1: day_name | Y1: month_name | Z1: season_name | AA1: weather_name | AB1: hour_label | AC1: time_block | AD1: temp_c | AE1: feels_like_c | AF1: humidity_pct | AG1: windspeed_kmh | AH1: registered_share | AI1: demand_level | AJ1: temp_band | AK1: cnt_sq | AL1: expected_cnt | AM1: z_score | AN1: anomaly_flag | AO1: rank_key | AP1: m_D1 | AQ1: m_D2 | AR1: m_D3
A2: 1 | B2: =IF($A2="","",IF($AP2<>"",INDEX(Raw_D1!$B$2:$B$1001,$AP2),IF($AR2<>"",INDEX(Raw_D3!$B$2:$B$1001,$AR2),""))) -> 40544 | C2: =IF($A2="","",IF($AP2<>"",INDEX(Raw_D1!$C$2:$C$1001,$AP2),IF($AR2<>"",INDEX(Raw_D3!$C$2:$C$1001,$AR2),""))) -> 1 | D2: =IF($A2="","",IF($AP2<>"",INDEX(Raw_D1!$D$2:$D$1001,$AP2),IF($AR2<>"",INDEX(Raw_D3!$D$2:$D$1001,$AR2),""))) -> 0 | E2: =IF($A2="","",IF($AP2<>"",INDEX(Raw_D1!$E$2:$E$1001,$AP2),IF($AR2<>"",INDEX(Raw_D3!$E$2:$E$1001,$AR2),""))) -> 1 | F2: =IF($A2="","",IF($AP2<>"",INDEX(Raw_D1!$F$2:$F$1001,$AP2),IF($AR2<>"",INDEX(Raw_D3!$F$2:$F$1001,$AR2),""))) -> 0 | G2: =IF($A2="","",IF($AP2<>"",IF(INDEX(Raw_D1!$G$2:$G$1001,$AP2),1,0),IF($AR2<>"",IF(INDEX(Raw_D3!$G$2:$G$1001,$AR2),1,0),""))) -> 0 | H2: =IF($A2="","",IF($AP2<>"",INDEX(Raw_D1!$H$2:$H$1001,$AP2),IF($AR2<>"",INDEX(Raw_D3!$H$2:$H$1001,$AR2),""))) -> 6 | I2: =IF($A2="","",IF($AP2<>"",INDEX(Raw_D1!$I$2:$I$1001,$AP2),IF($AR2<>"",INDEX(Raw_D3!$I$2:$I$1001,$AR2),""))) -> 1 | J2: =IF($A2="","",IF($AP2<>"",INDEX(Raw_D1!$J$2:$J$1001,$AP2),IF($AR2<>"",INDEX(Raw_D3!$J$2:$J$1001,$AR2),""))) -> 0.24 | K2: =IF($A2="","",IF($AQ2<>"",IF(INDEX(Raw_D2!$C$2:$C$1001,$AQ2)="","",INDEX(Raw_D2!$C$2:$C$1001,$AQ2)),IF($AR2<>"",IF(INDEX(Raw_D3!$K$2:$K$1001,$AR2)="","",INDEX(Raw_D3!$K$2:$K$1001,$AR2)),""))) -> 0.2879 | L2: =IF($A2="","",IF($AQ2<>"",IF(INDEX(Raw_D2!$D$2:$D$1001,$AQ2)="","",INDEX(Raw_D2!$D$2:$D$1001,$AQ2)),IF($AR2<>"",IF(INDEX(Raw_D3!$L$2:$L$1001,$AR2)="","",INDEX(Raw_D3!$L$2:$L$1001,$AR2)),""))) -> 0.81 | M2: =IF($A2="","",IF($AQ2<>"",IF(INDEX(Raw_D2!$E$2:$E$1001,$AQ2)="","",INDEX(Raw_D2!$E$2:$E$1001,$AQ2)),IF($AR2<>"",IF(INDEX(Raw_D3!$M$2:$M$1001,$AR2)="","",INDEX(Raw_D3!$M$2:$M$1001,$AR2)),""))) -> 0 | N2: =IF($A2="","",IF($AQ2<>"",IF(INDEX(Raw_D2!$F$2:$F$1001,$AQ2)="","",INDEX(Raw_D2!$F$2:$F$1001,$AQ2)),IF($AR2<>"",IF(INDEX(Raw_D3!$N$2:$N$1001,$AR2)="","",INDEX(Raw_D3!$N$2:$N$1001,$AR2)),""))) -> 3 | O2: =IF($A2="","",IF($AQ2<>"",IF(INDEX(Raw_D2!$G$2:$G$1001,$AQ2)="","",INDEX(Raw_D2!$G$2:$G$1001,$AQ2)),IF($AR2<>"",IF(INDEX(Raw_D3!$O$2:$O$1001,$AR2)="","",INDEX(Raw_D3!$O$2:$O$1001,$AR2)),""))) -> 13 | P2: =IF($A2="","",IF($AQ2<>"",IF(INDEX(Raw_D2!$H$2:$H$1001,$AQ2)="","",INDEX(Raw_D2!$H$2:$H$1001,$AQ2)),IF($AR2<>"",IF(INDEX(Raw_D3!$P$2:$P$1001,$AR2)="","",INDEX(Raw_D3!$P$2:$P$1001,$AR2)),""))) -> 16 | Q2: =IF($A2="","",IF(AND($AP2<>"",$AQ2<>""),"D1+D2",IF($AR2<>"","D3","Incomplete"))) -> D1+D2 | R2: =IF($A2="","",IF($K2="",IF($J2="","",ROUND(Lookups!$K$5+Lookups!$K$4*$J2,4)),$K2)) -> 0.2879 | S2: =IF($A2="","",IF($K2="","Imputed","Original")) -> Original | T2: =IF($A2="","",IF($P2="","Missing",IF($P2=$N2+$O2,"OK","Mismatch"))) -> OK | U2: =IF($A2="","",IF(COUNTIF($A$2:$A2,$A2)>1,"Duplicate","Unique")) -> Unique | V2: =IF($A2="","",IF(AND($U2="Unique",ISNUMBER($P2)),1,0)) -> 1 | W2: =IF($A2="","",IF(OR($H2=0,$H2=6),"Weekend","Weekday")) -> Weekend | X2: =IF($A2="","",TEXT($B2,"ddd")) -> Sat | Y2: =IF($A2="","",TEXT($B2,"mmm")) -> Jan | Z2: =IF($A2="","",IFERROR(VLOOKUP($C2,Lookups!$D$4:$E$7,2,FALSE),"Unknown")) -> Winter | AA2: =IF($A2="","",IFERROR(VLOOKUP($I2,Lookups!$A$4:$B$7,2,FALSE),"Unknown")) -> Clear | AB2: =IF($A2="","",TEXT($F2,"00")&":00") -> 00:00 | AC2: =IF($A2="","",VLOOKUP($F2,Lookups!$G$4:$H$8,2,TRUE)) -> Night (00-05) | AD2: =IF($A2="","",IF($J2="","",ROUND($J2*41,1))) -> 9.8 | AE2: =IF($A2="","",IF($R2="","",ROUND($R2*50,1))) -> 14.4 | AF2: =IF($A2="","",IF($L2="","",ROUND($L2*100,0))) -> 81 | AG2: =IF($A2="","",IF($M2="","",ROUND($M2*67,1))) -> 0 | AH2: =IF($A2="","",IF($P2="","",IF($P2=0,0,$O2/$P2))) -> 0.8125 | AI2: =IF($A2="","",IF($P2="","",IF($P2>=Lookups!$K$7,"High",IF($P2<=Lookups!$K$8,"Low","Medium")))) -> Low | AJ2: =IF($A2="","",IF($AD2="","",IF($AD2<5,"Under 5 C",IF($AD2<10,"5-10 C",IF($AD2<15,"10-15 C","15 C and above"))))) -> 5-10 C | AK2: =IF($A2="","",IF($P2="","",$P2^2)) -> 256 | AL2: =IF($V2<>1,"",AVERAGEIFS(Clean_Data!$P$2:$P$1001,Clean_Data!$F$2:$F$1001,$F2,Clean_Data!$W$2:$W$1001,$W2,Clean_Data!$V$2:$V$1001,1)) -> 28.071429 | AM2: =IF($V2<>1,"",IFERROR(($P2-$AL2)/SQRT(MAX(0,(SUMIFS(Clean_Data!$AK$2:$AK$1001,Clean_Data!$F$2:$F$1001,$F2,Clean_Data!$W$2:$W$1001,$W2,Clean_Data!$V$2:$V$1001,1)-COUNTIFS(Clean_Data!$F$2:$F$1001,$F2,Clean_Data!$W$2:$W$1001,$W2,Clean_Data!$V$2:$V$1001,1)*$AL2^2)/(COUNTIFS(Clean_Data!$F$2:$F$1001,$F2,Clean_Data!$W$2:$W$1001,$W2,Clean_Data!$V$2:$V$1001,1)-1))),"")) -> -1.3387748 | AN2: =IF($AM2="","",IF($AM2>=Lookups!$K$6,"High spike",IF($AM2<=-Lookups!$K$6,"Unusual low","Normal"))) -> Normal | AO2: =IF($V2<>1,"",$P2+ROW()/100000) -> 16.00002 | AP2: =IF($A2="","",IFERROR(MATCH($A2,Raw_D1!$A$2:$A$1001,0),"")) -> 1 | AQ2: =IF($A2="","",IFERROR(MATCH($A2,Raw_D2!$B$2:$B$1001,0),"")) -> 1 | AR2: =IF($A2="","",IFERROR(MATCH($A2,Raw_D3!$A$2:$A$1001,0),""))
A3: 2 | B3: =IF($A3="","",IF($AP3<>"",INDEX(Raw_D1!$B$2:$B$1001,$AP3),IF($AR3<>"",INDEX(Raw_D3!$B$2:$B$1001,$AR3),""))) -> 40544 | C3: =IF($A3="","",IF($AP3<>"",INDEX(Raw_D1!$C$2:$C$1001,$AP3),IF($AR3<>"",INDEX(Raw_D3!$C$2:$C$1001,$AR3),""))) -> 1 | D3: =IF($A3="","",IF($AP3<>"",INDEX(Raw_D1!$D$2:$D$1001,$AP3),IF($AR3<>"",INDEX(Raw_D3!$D$2:$D$1001,$AR3),""))) -> 0 | E3: =IF($A3="","",IF($AP3<>"",INDEX(Raw_D1!$E$2:$E$1001,$AP3),IF($AR3<>"",INDEX(Raw_D3!$E$2:$E$1001,$AR3),""))) -> 1 | F3: =IF($A3="","",IF($AP3<>"",INDEX(Raw_D1!$F$2:$F$1001,$AP3),IF($AR3<>"",INDEX(Raw_D3!$F$2:$F$1001,$AR3),""))) -> 1 | G3: =IF($A3="","",IF($AP3<>"",IF(INDEX(Raw_D1!$G$2:$G$1001,$AP3),1,0),IF($AR3<>"",IF(INDEX(Raw_D3!$G$2:$G$1001,$AR3),1,0),""))) -> 0 | H3: =IF($A3="","",IF($AP3<>"",INDEX(Raw_D1!$H$2:$H$1001,$AP3),IF($AR3<>"",INDEX(Raw_D3!$H$2:$H$1001,$AR3),""))) -> 6 | I3: =IF($A3="","",IF($AP3<>"",INDEX(Raw_D1!$I$2:$I$1001,$AP3),IF($AR3<>"",INDEX(Raw_D3!$I$2:$I$1001,$AR3),""))) -> 1 | J3: =IF($A3="","",IF($AP3<>"",INDEX(Raw_D1!$J$2:$J$1001,$AP3),IF($AR3<>"",INDEX(Raw_D3!$J$2:$J$1001,$AR3),""))) -> 0.22 | K3: =IF($A3="","",IF($AQ3<>"",IF(INDEX(Raw_D2!$C$2:$C$1001,$AQ3)="","",INDEX(Raw_D2!$C$2:$C$1001,$AQ3)),IF($AR3<>"",IF(INDEX(Raw_D3!$K$2:$K$1001,$AR3)="","",INDEX(Raw_D3!$K$2:$K$1001,$AR3)),""))) -> 0.2727 | L3: =IF($A3="","",IF($AQ3<>"",IF(INDEX(Raw_D2!$D$2:$D$1001,$AQ3)="","",INDEX(Raw_D2!$D$2:$D$1001,$AQ3)),IF($AR3<>"",IF(INDEX(Raw_D3!$L$2:$L$1001,$AR3)="","",INDEX(Raw_D3!$L$2:$L$1001,$AR3)),""))) -> 0.8 | M3: =IF($A3="","",IF($AQ3<>"",IF(INDEX(Raw_D2!$E$2:$E$1001,$AQ3)="","",INDEX(Raw_D2!$E$2:$E$1001,$AQ3)),IF($AR3<>"",IF(INDEX(Raw_D3!$M$2:$M$1001,$AR3)="","",INDEX(Raw_D3!$M$2:$M$1001,$AR3)),""))) -> 0 | N3: =IF($A3="","",IF($AQ3<>"",IF(INDEX(Raw_D2!$F$2:$F$1001,$AQ3)="","",INDEX(Raw_D2!$F$2:$F$1001,$AQ3)),IF($AR3<>"",IF(INDEX(Raw_D3!$N$2:$N$1001,$AR3)="","",INDEX(Raw_D3!$N$2:$N$1001,$AR3)),""))) -> 8 | O3: =IF($A3="","",IF($AQ3<>"",IF(INDEX(Raw_D2!$G$2:$G$1001,$AQ3)="","",INDEX(Raw_D2!$G$2:$G$1001,$AQ3)),IF($AR3<>"",IF(INDEX(Raw_D3!$O$2:$O$1001,$AR3)="","",INDEX(Raw_D3!$O$2:$O$1001,$AR3)),""))) -> 32 | P3: =IF($A3="","",IF($AQ3<>"",IF(INDEX(Raw_D2!$H$2:$H$1001,$AQ3)="","",INDEX(Raw_D2!$H$2:$H$1001,$AQ3)),IF($AR3<>"",IF(INDEX(Raw_D3!$P$2:$P$1001,$AR3)="","",INDEX(Raw_D3!$P$2:$P$1001,$AR3)),""))) -> 40 | Q3: =IF($A3="","",IF(AND($AP3<>"",$AQ3<>""),"D1+D2",IF($AR3<>"","D3","Incomplete"))) -> D1+D2 | R3: =IF($A3="","",IF($K3="",IF($J3="","",ROUND(Lookups!$K$5+Lookups!$K$4*$J3,4)),$K3)) -> 0.2727 | S3: =IF($A3="","",IF($K3="","Imputed","Original")) -> Original | T3: =IF($A3="","",IF($P3="","Missing",IF($P3=$N3+$O3,"OK","Mismatch"))) -> OK | U3: =IF($A3="","",IF(COUNTIF($A$2:$A3,$A3)>1,"Duplicate","Unique")) -> Unique | V3: =IF($A3="","",IF(AND($U3="Unique",ISNUMBER($P3)),1,0)) -> 1 | W3: =IF($A3="","",IF(OR($H3=0,$H3=6),"Weekend","Weekday")) -> Weekend | X3: =IF($A3="","",TEXT($B3,"ddd")) -> Sat | Y3: =IF($A3="","",TEXT($B3,"mmm")) -> Jan | Z3: =IF($A3="","",IFERROR(VLOOKUP($C3,Lookups!$D$4:$E$7,2,FALSE),"Unknown")) -> Winter | AA3: =IF($A3="","",IFERROR(VLOOKUP($I3,Lookups!$A$4:$B$7,2,FALSE),"Unknown")) -> Clear | AB3: =IF($A3="","",TEXT($F3,"00")&":00") -> 01:00 | AC3: =IF($A3="","",VLOOKUP($F3,Lookups!$G$4:$H$8,2,TRUE)) -> Night (00-05) | AD3: =IF($A3="","",IF($J3="","",ROUND($J3*41,1))) -> 9 | AE3: =IF($A3="","",IF($R3="","",ROUND($R3*50,1))) -> 13.6 | AF3: =IF($A3="","",IF($L3="","",ROUND($L3*100,0))) -> 80 | AG3: =IF($A3="","",IF($M3="","",ROUND($M3*67,1))) -> 0 | AH3: =IF($A3="","",IF($P3="","",IF($P3=0,0,$O3/$P3))) -> 0.8 | AI3: =IF($A3="","",IF($P3="","",IF($P3>=Lookups!$K$7,"High",IF($P3<=Lookups!$K$8,"Low","Medium")))) -> Medium | AJ3: =IF($A3="","",IF($AD3="","",IF($AD3<5,"Under 5 C",IF($AD3<10,"5-10 C",IF($AD3<15,"10-15 C","15 C and above"))))) -> 5-10 C | AK3: =IF($A3="","",IF($P3="","",$P3^2)) -> 1600 | AL3: =IF($V3<>1,"",AVERAGEIFS(Clean_Data!$P$2:$P$1001,Clean_Data!$F$2:$F$1001,$F3,Clean_Data!$W$2:$W$1001,$W3,Clean_Data!$V$2:$V$1001,1)) -> 22.285714 | AM3: =IF($V3<>1,"",IFERROR(($P3-$AL3)/SQRT(MAX(0,(SUMIFS(Clean_Data!$AK$2:$AK$1001,Clean_Data!$F$2:$F$1001,$F3,Clean_Data!$W$2:$W$1001,$W3,Clean_Data!$V$2:$V$1001,1)-COUNTIFS(Clean_Data!$F$2:$F$1001,$F3,Clean_Data!$W$2:$W$1001,$W3,Clean_Data!$V$2:$V$1001,1)*$AL3^2)/(COUNTIFS(Clean_Data!$F$2:$F$1001,$F3,Clean_Data!$W$2:$W$1001,$W3,Clean_Data!$V$2:$V$1001,1)-1))),"")) -> 1.8205034 | AN3: =IF($AM3="","",IF($AM3>=Lookups!$K$6,"High spike",IF($AM3<=-Lookups!$K$6,"Unusual low","Normal"))) -> Normal | AO3: =IF($V3<>1,"",$P3+ROW()/100000) -> 40.00003 | AP3: =IF($A3="","",IFERROR(MATCH($A3,Raw_D1!$A$2:$A$1001,0),"")) -> 2 | AQ3: =IF($A3="","",IFERROR(MATCH($A3,Raw_D2!$B$2:$B$1001,0),"")) -> 2 | AR3: =IF($A3="","",IFERROR(MATCH($A3,Raw_D3!$A$2:$A$1001,0),""))
A4: 3 | B4: =IF($A4="","",IF($AP4<>"",INDEX(Raw_D1!$B$2:$B$1001,$AP4),IF($AR4<>"",INDEX(Raw_D3!$B$2:$B$1001,$AR4),""))) -> 40544 | C4: =IF($A4="","",IF($AP4<>"",INDEX(Raw_D1!$C$2:$C$1001,$AP4),IF($AR4<>"",INDEX(Raw_D3!$C$2:$C$1001,$AR4),""))) -> 1 | D4: =IF($A4="","",IF($AP4<>"",INDEX(Raw_D1!$D$2:$D$1001,$AP4),IF($AR4<>"",INDEX(Raw_D3!$D$2:$D$1001,$AR4),""))) -> 0 | E4: =IF($A4="","",IF($AP4<>"",INDEX(Raw_D1!$E$2:$E$1001,$AP4),IF($AR4<>"",INDEX(Raw_D3!$E$2:$E$1001,$AR4),""))) -> 1 | F4: =IF($A4="","",IF($AP4<>"",INDEX(Raw_D1!$F$2:$F$1001,$AP4),IF($AR4<>"",INDEX(Raw_D3!$F$2:$F$1001,$AR4),""))) -> 2 | G4: =IF($A4="","",IF($AP4<>"",IF(INDEX(Raw_D1!$G$2:$G$1001,$AP4),1,0),IF($AR4<>"",IF(INDEX(Raw_D3!$G$2:$G$1001,$AR4),1,0),""))) -> 0 | H4: =IF($A4="","",IF($AP4<>"",INDEX(Raw_D1!$H$2:$H$1001,$AP4),IF($AR4<>"",INDEX(Raw_D3!$H$2:$H$1001,$AR4),""))) -> 6 | I4: =IF($A4="","",IF($AP4<>"",INDEX(Raw_D1!$I$2:$I$1001,$AP4),IF($AR4<>"",INDEX(Raw_D3!$I$2:$I$1001,$AR4),""))) -> 1 | J4: =IF($A4="","",IF($AP4<>"",INDEX(Raw_D1!$J$2:$J$1001,$AP4),IF($AR4<>"",INDEX(Raw_D3!$J$2:$J$1001,$AR4),""))) -> 0.22 | K4: =IF($A4="","",IF($AQ4<>"",IF(INDEX(Raw_D2!$C$2:$C$1001,$AQ4)="","",INDEX(Raw_D2!$C$2:$C$1001,$AQ4)),IF($AR4<>"",IF(INDEX(Raw_D3!$K$2:$K$1001,$AR4)="","",INDEX(Raw_D3!$K$2:$K$1001,$AR4)),""))) -> 0.2727 | L4: =IF($A4="","",IF($AQ4<>"",IF(INDEX(Raw_D2!$D$2:$D$1001,$AQ4)="","",INDEX(Raw_D2!$D$2:$D$1001,$AQ4)),IF($AR4<>"",IF(INDEX(Raw_D3!$L$2:$L$1001,$AR4)="","",INDEX(Raw_D3!$L$2:$L$1001,$AR4)),""))) -> 0.8 | M4: =IF($A4="","",IF($AQ4<>"",IF(INDEX(Raw_D2!$E$2:$E$1001,$AQ4)="","",INDEX(Raw_D2!$E$2:$E$1001,$AQ4)),IF($AR4<>"",IF(INDEX(Raw_D3!$M$2:$M$1001,$AR4)="","",INDEX(Raw_D3!$M$2:$M$1001,$AR4)),""))) -> 0 | N4: =IF($A4="","",IF($AQ4<>"",IF(INDEX(Raw_D2!$F$2:$F$1001,$AQ4)="","",INDEX(Raw_D2!$F$2:$F$1001,$AQ4)),IF($AR4<>"",IF(INDEX(Raw_D3!$N$2:$N$1001,$AR4)="","",INDEX(Raw_D3!$N$2:$N$1001,$AR4)),""))) -> 5 | O4: =IF($A4="","",IF($AQ4<>"",IF(INDEX(Raw_D2!$G$2:$G$1001,$AQ4)="","",INDEX(Raw_D2!$G$2:$G$1001,$AQ4)),IF($AR4<>"",IF(INDEX(Raw_D3!$O$2:$O$1001,$AR4)="","",INDEX(Raw_D3!$O$2:$O$1001,$AR4)),""))) -> 27 | P4: =IF($A4="","",IF($AQ4<>"",IF(INDEX(Raw_D2!$H$2:$H$1001,$AQ4)="","",INDEX(Raw_D2!$H$2:$H$1001,$AQ4)),IF($AR4<>"",IF(INDEX(Raw_D3!$P$2:$P$1001,$AR4)="","",INDEX(Raw_D3!$P$2:$P$1001,$AR4)),""))) -> 32 | Q4: =IF($A4="","",IF(AND($AP4<>"",$AQ4<>""),"D1+D2",IF($AR4<>"","D3","Incomplete"))) -> D1+D2 | R4: =IF($A4="","",IF($K4="",IF($J4="","",ROUND(Lookups!$K$5+Lookups!$K$4*$J4,4)),$K4)) -> 0.2727 | S4: =IF($A4="","",IF($K4="","Imputed","Original")) -> Original | T4: =IF($A4="","",IF($P4="","Missing",IF($P4=$N4+$O4,"OK","Mismatch"))) -> OK | U4: =IF($A4="","",IF(COUNTIF($A$2:$A4,$A4)>1,"Duplicate","Unique")) -> Unique | V4: =IF($A4="","",IF(AND($U4="Unique",ISNUMBER($P4)),1,0)) -> 1 | W4: =IF($A4="","",IF(OR($H4=0,$H4=6),"Weekend","Weekday")) -> Weekend | X4: =IF($A4="","",TEXT($B4,"ddd")) -> Sat | Y4: =IF($A4="","",TEXT($B4,"mmm")) -> Jan | Z4: =IF($A4="","",IFERROR(VLOOKUP($C4,Lookups!$D$4:$E$7,2,FALSE),"Unknown")) -> Winter | AA4: =IF($A4="","",IFERROR(VLOOKUP($I4,Lookups!$A$4:$B$7,2,FALSE),"Unknown")) -> Clear | AB4: =IF($A4="","",TEXT($F4,"00")&":00") -> 02:00 | AC4: =IF($A4="","",VLOOKUP($F4,Lookups!$G$4:$H$8,2,TRUE)) -> Night (00-05) | AD4: =IF($A4="","",IF($J4="","",ROUND($J4*41,1))) -> 9 | AE4: =IF($A4="","",IF($R4="","",ROUND($R4*50,1))) -> 13.6 | AF4: =IF($A4="","",IF($L4="","",ROUND($L4*100,0))) -> 80 | AG4: =IF($A4="","",IF($M4="","",ROUND($M4*67,1))) -> 0 | AH4: =IF($A4="","",IF($P4="","",IF($P4=0,0,$O4/$P4))) -> 0.84375 | AI4: =IF($A4="","",IF($P4="","",IF($P4>=Lookups!$K$7,"High",IF($P4<=Lookups!$K$8,"Low","Medium")))) -> Medium | AJ4: =IF($A4="","",IF($AD4="","",IF($AD4<5,"Under 5 C",IF($AD4<10,"5-10 C",IF($AD4<15,"10-15 C","15 C and above"))))) -> 5-10 C | AK4: =IF($A4="","",IF($P4="","",$P4^2)) -> 1024 | AL4: =IF($V4<>1,"",AVERAGEIFS(Clean_Data!$P$2:$P$1001,Clean_Data!$F$2:$F$1001,$F4,Clean_Data!$W$2:$W$1001,$W4,Clean_Data!$V$2:$V$1001,1)) -> 15.928571 | AM4: =IF($V4<>1,"",IFERROR(($P4-$AL4)/SQRT(MAX(0,(SUMIFS(Clean_Data!$AK$2:$AK$1001,Clean_Data!$F$2:$F$1001,$F4,Clean_Data!$W$2:$W$1001,$W4,Clean_Data!$V$2:$V$1001,1)-COUNTIFS(Clean_Data!$F$2:$F$1001,$F4,Clean_Data!$W$2:$W$1001,$W4,Clean_Data!$V$2:$V$1001,1)*$AL4^2)/(COUNTIFS(Clean_Data!$F$2:$F$1001,$F4,Clean_Data!$W$2:$W$1001,$W4,Clean_Data!$V$2:$V$1001,1)-1))),"")) -> 2.7785434 | AN4: =IF($AM4="","",IF($AM4>=Lookups!$K$6,"High spike",IF($AM4<=-Lookups!$K$6,"Unusual low","Normal"))) -> Normal | AO4: =IF($V4<>1,"",$P4+ROW()/100000) -> 32.00004 | AP4: =IF($A4="","",IFERROR(MATCH($A4,Raw_D1!$A$2:$A$1001,0),"")) -> 3 | AQ4: =IF($A4="","",IFERROR(MATCH($A4,Raw_D2!$B$2:$B$1001,0),"")) -> 3 | AR4: =IF($A4="","",IFERROR(MATCH($A4,Raw_D3!$A$2:$A$1001,0),""))
A5: 4 | B5: =IF($A5="","",IF($AP5<>"",INDEX(Raw_D1!$B$2:$B$1001,$AP5),IF($AR5<>"",INDEX(Raw_D3!$B$2:$B$1001,$AR5),""))) -> 40544 | C5: =IF($A5="","",IF($AP5<>"",INDEX(Raw_D1!$C$2:$C$1001,$AP5),IF($AR5<>"",INDEX(Raw_D3!$C$2:$C$1001,$AR5),""))) -> 1 | D5: =IF($A5="","",IF($AP5<>"",INDEX(Raw_D1!$D$2:$D$1001,$AP5),IF($AR5<>"",INDEX(Raw_D3!$D$2:$D$1001,$AR5),""))) -> 0 | E5: =IF($A5="","",IF($AP5<>"",INDEX(Raw_D1!$E$2:$E$1001,$AP5),IF($AR5<>"",INDEX(Raw_D3!$E$2:$E$1001,$AR5),""))) -> 1 | F5: =IF($A5="","",IF($AP5<>"",INDEX(Raw_D1!$F$2:$F$1001,$AP5),IF($AR5<>"",INDEX(Raw_D3!$F$2:$F$1001,$AR5),""))) -> 3 | G5: =IF($A5="","",IF($AP5<>"",IF(INDEX(Raw_D1!$G$2:$G$1001,$AP5),1,0),IF($AR5<>"",IF(INDEX(Raw_D3!$G$2:$G$1001,$AR5),1,0),""))) -> 0 | H5: =IF($A5="","",IF($AP5<>"",INDEX(Raw_D1!$H$2:$H$1001,$AP5),IF($AR5<>"",INDEX(Raw_D3!$H$2:$H$1001,$AR5),""))) -> 6 | I5: =IF($A5="","",IF($AP5<>"",INDEX(Raw_D1!$I$2:$I$1001,$AP5),IF($AR5<>"",INDEX(Raw_D3!$I$2:$I$1001,$AR5),""))) -> 1 | J5: =IF($A5="","",IF($AP5<>"",INDEX(Raw_D1!$J$2:$J$1001,$AP5),IF($AR5<>"",INDEX(Raw_D3!$J$2:$J$1001,$AR5),""))) -> 0.24 | K5: =IF($A5="","",IF($AQ5<>"",IF(INDEX(Raw_D2!$C$2:$C$1001,$AQ5)="","",INDEX(Raw_D2!$C$2:$C$1001,$AQ5)),IF($AR5<>"",IF(INDEX(Raw_D3!$K$2:$K$1001,$AR5)="","",INDEX(Raw_D3!$K$2:$K$1001,$AR5)),""))) -> 0.2879 | L5: =IF($A5="","",IF($AQ5<>"",IF(INDEX(Raw_D2!$D$2:$D$1001,$AQ5)="","",INDEX(Raw_D2!$D$2:$D$1001,$AQ5)),IF($AR5<>"",IF(INDEX(Raw_D3!$L$2:$L$1001,$AR5)="","",INDEX(Raw_D3!$L$2:$L$1001,$AR5)),""))) -> 0.75 | M5: =IF($A5="","",IF($AQ5<>"",IF(INDEX(Raw_D2!$E$2:$E$1001,$AQ5)="","",INDEX(Raw_D2!$E$2:$E$1001,$AQ5)),IF($AR5<>"",IF(INDEX(Raw_D3!$M$2:$M$1001,$AR5)="","",INDEX(Raw_D3!$M$2:$M$1001,$AR5)),""))) -> 0 | N5: =IF($A5="","",IF($AQ5<>"",IF(INDEX(Raw_D2!$F$2:$F$1001,$AQ5)="","",INDEX(Raw_D2!$F$2:$F$1001,$AQ5)),IF($AR5<>"",IF(INDEX(Raw_D3!$N$2:$N$1001,$AR5)="","",INDEX(Raw_D3!$N$2:$N$1001,$AR5)),""))) -> 3 | O5: =IF($A5="","",IF($AQ5<>"",IF(INDEX(Raw_D2!$G$2:$G$1001,$AQ5)="","",INDEX(Raw_D2!$G$2:$G$1001,$AQ5)),IF($AR5<>"",IF(INDEX(Raw_D3!$O$2:$O$1001,$AR5)="","",INDEX(Raw_D3!$O$2:$O$1001,$AR5)),""))) -> 10 | P5: =IF($A5="","",IF($AQ5<>"",IF(INDEX(Raw_D2!$H$2:$H$1001,$AQ5)="","",INDEX(Raw_D2!$H$2:$H$1001,$AQ5)),IF($AR5<>"",IF(INDEX(Raw_D3!$P$2:$P$1001,$AR5)="","",INDEX(Raw_D3!$P$2:$P$1001,$AR5)),""))) -> 13 | Q5: =IF($A5="","",IF(AND($AP5<>"",$AQ5<>""),"D1+D2",IF($AR5<>"","D3","Incomplete"))) -> D1+D2 | R5: =IF($A5="","",IF($K5="",IF($J5="","",ROUND(Lookups!$K$5+Lookups!$K$4*$J5,4)),$K5)) -> 0.2879 | S5: =IF($A5="","",IF($K5="","Imputed","Original")) -> Original | T5: =IF($A5="","",IF($P5="","Missing",IF($P5=$N5+$O5,"OK","Mismatch"))) -> OK | U5: =IF($A5="","",IF(COUNTIF($A$2:$A5,$A5)>1,"Duplicate","Unique")) -> Unique | V5: =IF($A5="","",IF(AND($U5="Unique",ISNUMBER($P5)),1,0)) -> 1 | W5: =IF($A5="","",IF(OR($H5=0,$H5=6),"Weekend","Weekday")) -> Weekend | X5: =IF($A5="","",TEXT($B5,"ddd")) -> Sat | Y5: =IF($A5="","",TEXT($B5,"mmm")) -> Jan | Z5: =IF($A5="","",IFERROR(VLOOKUP($C5,Lookups!$D$4:$E$7,2,FALSE),"Unknown")) -> Winter | AA5: =IF($A5="","",IFERROR(VLOOKUP($I5,Lookups!$A$4:$B$7,2,FALSE),"Unknown")) -> Clear | AB5: =IF($A5="","",TEXT($F5,"00")&":00") -> 03:00 | AC5: =IF($A5="","",VLOOKUP($F5,Lookups!$G$4:$H$8,2,TRUE)) -> Night (00-05) | AD5: =IF($A5="","",IF($J5="","",ROUND($J5*41,1))) -> 9.8 | AE5: =IF($A5="","",IF($R5="","",ROUND($R5*50,1))) -> 14.4 | AF5: =IF($A5="","",IF($L5="","",ROUND($L5*100,0))) -> 75 | AG5: =IF($A5="","",IF($M5="","",ROUND($M5*67,1))) -> 0 | AH5: =IF($A5="","",IF($P5="","",IF($P5=0,0,$O5/$P5))) -> 0.76923077 | AI5: =IF($A5="","",IF($P5="","",IF($P5>=Lookups!$K$7,"High",IF($P5<=Lookups!$K$8,"Low","Medium")))) -> Low | AJ5: =IF($A5="","",IF($AD5="","",IF($AD5<5,"Under 5 C",IF($AD5<10,"5-10 C",IF($AD5<15,"10-15 C","15 C and above"))))) -> 5-10 C | AK5: =IF($A5="","",IF($P5="","",$P5^2)) -> 169 | AL5: =IF($V5<>1,"",AVERAGEIFS(Clean_Data!$P$2:$P$1001,Clean_Data!$F$2:$F$1001,$F5,Clean_Data!$W$2:$W$1001,$W5,Clean_Data!$V$2:$V$1001,1)) -> 9.0714286 | AM5: =IF($V5<>1,"",IFERROR(($P5-$AL5)/SQRT(MAX(0,(SUMIFS(Clean_Data!$AK$2:$AK$1001,Clean_Data!$F$2:$F$1001,$F5,Clean_Data!$W$2:$W$1001,$W5,Clean_Data!$V$2:$V$1001,1)-COUNTIFS(Clean_Data!$F$2:$F$1001,$F5,Clean_Data!$W$2:$W$1001,$W5,Clean_Data!$V$2:$V$1001,1)*$AL5^2)/(COUNTIFS(Clean_Data!$F$2:$F$1001,$F5,Clean_Data!$W$2:$W$1001,$W5,Clean_Data!$V$2:$V$1001,1)-1))),"")) -> 1.1848048 | AN5: =IF($AM5="","",IF($AM5>=Lookups!$K$6,"High spike",IF($AM5<=-Lookups!$K$6,"Unusual low","Normal"))) -> Normal | AO5: =IF($V5<>1,"",$P5+ROW()/100000) -> 13.00005 | AP5: =IF($A5="","",IFERROR(MATCH($A5,Raw_D1!$A$2:$A$1001,0),"")) -> 4 | AQ5: =IF($A5="","",IFERROR(MATCH($A5,Raw_D2!$B$2:$B$1001,0),"")) -> 4 | AR5: =IF($A5="","",IFERROR(MATCH($A5,Raw_D3!$A$2:$A$1001,0),""))
A6: 5 | B6: =IF($A6="","",IF($AP6<>"",INDEX(Raw_D1!$B$2:$B$1001,$AP6),IF($AR6<>"",INDEX(Raw_D3!$B$2:$B$1001,$AR6),""))) -> 40544 | C6: =IF($A6="","",IF($AP6<>"",INDEX(Raw_D1!$C$2:$C$1001,$AP6),IF($AR6<>"",INDEX(Raw_D3!$C$2:$C$1001,$AR6),""))) -> 1 | D6: =IF($A6="","",IF($AP6<>"",INDEX(Raw_D1!$D$2:$D$1001,$AP6),IF($AR6<>"",INDEX(Raw_D3!$D$2:$D$1001,$AR6),""))) -> 0 | E6: =IF($A6="","",IF($AP6<>"",INDEX(Raw_D1!$E$2:$E$1001,$AP6),IF($AR6<>"",INDEX(Raw_D3!$E$2:$E$1001,$AR6),""))) -> 1 | F6: =IF($A6="","",IF($AP6<>"",INDEX(Raw_D1!$F$2:$F$1001,$AP6),IF($AR6<>"",INDEX(Raw_D3!$F$2:$F$1001,$AR6),""))) -> 4 | G6: =IF($A6="","",IF($AP6<>"",IF(INDEX(Raw_D1!$G$2:$G$1001,$AP6),1,0),IF($AR6<>"",IF(INDEX(Raw_D3!$G$2:$G$1001,$AR6),1,0),""))) -> 0 | H6: =IF($A6="","",IF($AP6<>"",INDEX(Raw_D1!$H$2:$H$1001,$AP6),IF($AR6<>"",INDEX(Raw_D3!$H$2:$H$1001,$AR6),""))) -> 6 | I6: =IF($A6="","",IF($AP6<>"",INDEX(Raw_D1!$I$2:$I$1001,$AP6),IF($AR6<>"",INDEX(Raw_D3!$I$2:$I$1001,$AR6),""))) -> 1 | J6: =IF($A6="","",IF($AP6<>"",INDEX(Raw_D1!$J$2:$J$1001,$AP6),IF($AR6<>"",INDEX(Raw_D3!$J$2:$J$1001,$AR6),""))) -> 0.24 | K6: =IF($A6="","",IF($AQ6<>"",IF(INDEX(Raw_D2!$C$2:$C$1001,$AQ6)="","",INDEX(Raw_D2!$C$2:$C$1001,$AQ6)),IF($AR6<>"",IF(INDEX(Raw_D3!$K$2:$K$1001,$AR6)="","",INDEX(Raw_D3!$K$2:$K$1001,$AR6)),""))) -> 0.2879 | L6: =IF($A6="","",IF($AQ6<>"",IF(INDEX(Raw_D2!$D$2:$D$1001,$AQ6)="","",INDEX(Raw_D2!$D$2:$D$1001,$AQ6)),IF($AR6<>"",IF(INDEX(Raw_D3!$L$2:$L$1001,$AR6)="","",INDEX(Raw_D3!$L$2:$L$1001,$AR6)),""))) -> 0.75 | M6: =IF($A6="","",IF($AQ6<>"",IF(INDEX(Raw_D2!$E$2:$E$1001,$AQ6)="","",INDEX(Raw_D2!$E$2:$E$1001,$AQ6)),IF($AR6<>"",IF(INDEX(Raw_D3!$M$2:$M$1001,$AR6)="","",INDEX(Raw_D3!$M$2:$M$1001,$AR6)),""))) -> 0 | N6: =IF($A6="","",IF($AQ6<>"",IF(INDEX(Raw_D2!$F$2:$F$1001,$AQ6)="","",INDEX(Raw_D2!$F$2:$F$1001,$AQ6)),IF($AR6<>"",IF(INDEX(Raw_D3!$N$2:$N$1001,$AR6)="","",INDEX(Raw_D3!$N$2:$N$1001,$AR6)),""))) -> 0 | O6: =IF($A6="","",IF($AQ6<>"",IF(INDEX(Raw_D2!$G$2:$G$1001,$AQ6)="","",INDEX(Raw_D2!$G$2:$G$1001,$AQ6)),IF($AR6<>"",IF(INDEX(Raw_D3!$O$2:$O$1001,$AR6)="","",INDEX(Raw_D3!$O$2:$O$1001,$AR6)),""))) -> 1 | P6: =IF($A6="","",IF($AQ6<>"",IF(INDEX(Raw_D2!$H$2:$H$1001,$AQ6)="","",INDEX(Raw_D2!$H$2:$H$1001,$AQ6)),IF($AR6<>"",IF(INDEX(Raw_D3!$P$2:$P$1001,$AR6)="","",INDEX(Raw_D3!$P$2:$P$1001,$AR6)),""))) -> 1 | Q6: =IF($A6="","",IF(AND($AP6<>"",$AQ6<>""),"D1+D2",IF($AR6<>"","D3","Incomplete"))) -> D1+D2 | R6: =IF($A6="","",IF($K6="",IF($J6="","",ROUND(Lookups!$K$5+Lookups!$K$4*$J6,4)),$K6)) -> 0.2879 | S6: =IF($A6="","",IF($K6="","Imputed","Original")) -> Original | T6: =IF($A6="","",IF($P6="","Missing",IF($P6=$N6+$O6,"OK","Mismatch"))) -> OK | U6: =IF($A6="","",IF(COUNTIF($A$2:$A6,$A6)>1,"Duplicate","Unique")) -> Unique | V6: =IF($A6="","",IF(AND($U6="Unique",ISNUMBER($P6)),1,0)) -> 1 | W6: =IF($A6="","",IF(OR($H6=0,$H6=6),"Weekend","Weekday")) -> Weekend | X6: =IF($A6="","",TEXT($B6,"ddd")) -> Sat | Y6: =IF($A6="","",TEXT($B6,"mmm")) -> Jan | Z6: =IF($A6="","",IFERROR(VLOOKUP($C6,Lookups!$D$4:$E$7,2,FALSE),"Unknown")) -> Winter | AA6: =IF($A6="","",IFERROR(VLOOKUP($I6,Lookups!$A$4:$B$7,2,FALSE),"Unknown")) -> Clear | AB6: =IF($A6="","",TEXT($F6,"00")&":00") -> 04:00 | AC6: =IF($A6="","",VLOOKUP($F6,Lookups!$G$4:$H$8,2,TRUE)) -> Night (00-05) | AD6: =IF($A6="","",IF($J6="","",ROUND($J6*41,1))) -> 9.8 | AE6: =IF($A6="","",IF($R6="","",ROUND($R6*50,1))) -> 14.4 | AF6: =IF($A6="","",IF($L6="","",ROUND($L6*100,0))) -> 75 | AG6: =IF($A6="","",IF($M6="","",ROUND($M6*67,1))) -> 0 | AH6: =IF($A6="","",IF($P6="","",IF($P6=0,0,$O6/$P6))) -> 1 | AI6: =IF($A6="","",IF($P6="","",IF($P6>=Lookups!$K$7,"High",IF($P6<=Lookups!$K$8,"Low","Medium")))) -> Low | AJ6: =IF($A6="","",IF($AD6="","",IF($AD6<5,"Under 5 C",IF($AD6<10,"5-10 C",IF($AD6<15,"10-15 C","15 C and above"))))) -> 5-10 C | AK6: =IF($A6="","",IF($P6="","",$P6^2)) -> 1 | AL6: =IF($V6<>1,"",AVERAGEIFS(Clean_Data!$P$2:$P$1001,Clean_Data!$F$2:$F$1001,$F6,Clean_Data!$W$2:$W$1001,$W6,Clean_Data!$V$2:$V$1001,1)) -> 2.6923077 | AM6: =IF($V6<>1,"",IFERROR(($P6-$AL6)/SQRT(MAX(0,(SUMIFS(Clean_Data!$AK$2:$AK$1001,Clean_Data!$F$2:$F$1001,$F6,Clean_Data!$W$2:$W$1001,$W6,Clean_Data!$V$2:$V$1001,1)-COUNTIFS(Clean_Data!$F$2:$F$1001,$F6,Clean_Data!$W$2:$W$1001,$W6,Clean_Data!$V$2:$V$1001,1)*$AL6^2)/(COUNTIFS(Clean_Data!$F$2:$F$1001,$F6,Clean_Data!$W$2:$W$1001,$W6,Clean_Data!$V$2:$V$1001,1)-1))),"")) -> -0.82275335 | AN6: =IF($AM6="","",IF($AM6>=Lookups!$K$6,"High spike",IF($AM6<=-Lookups!$K$6,"Unusual low","Normal"))) -> Normal | AO6: =IF($V6<>1,"",$P6+ROW()/100000) -> 1.00006 | AP6: =IF($A6="","",IFERROR(MATCH($A6,Raw_D1!$A$2:$A$1001,0),"")) -> 5 | AQ6: =IF($A6="","",IFERROR(MATCH($A6,Raw_D2!$B$2:$B$1001,0),"")) -> 5 | AR6: =IF($A6="","",IFERROR(MATCH($A6,Raw_D3!$A$2:$A$1001,0),""))
A7: 6 | B7: =IF($A7="","",IF($AP7<>"",INDEX(Raw_D1!$B$2:$B$1001,$AP7),IF($AR7<>"",INDEX(Raw_D3!$B$2:$B$1001,$AR7),""))) -> 40544 | C7: =IF($A7="","",IF($AP7<>"",INDEX(Raw_D1!$C$2:$C$1001,$AP7),IF($AR7<>"",INDEX(Raw_D3!$C$2:$C$1001,$AR7),""))) -> 1 | D7: =IF($A7="","",IF($AP7<>"",INDEX(Raw_D1!$D$2:$D$1001,$AP7),IF($AR7<>"",INDEX(Raw_D3!$D$2:$D$1001,$AR7),""))) -> 0 | E7: =IF($A7="","",IF($AP7<>"",INDEX(Raw_D1!$E$2:$E$1001,$AP7),IF($AR7<>"",INDEX(Raw_D3!$E$2:$E$1001,$AR7),""))) -> 1 | F7: =IF($A7="","",IF($AP7<>"",INDEX(Raw_D1!$F$2:$F$1001,$AP7),IF($AR7<>"",INDEX(Raw_D3!$F$2:$F$1001,$AR7),""))) -> 5 | G7: =IF($A7="","",IF($AP7<>"",IF(INDEX(Raw_D1!$G$2:$G$1001,$AP7),1,0),IF($AR7<>"",IF(INDEX(Raw_D3!$G$2:$G$1001,$AR7),1,0),""))) -> 0 | H7: =IF($A7="","",IF($AP7<>"",INDEX(Raw_D1!$H$2:$H$1001,$AP7),IF($AR7<>"",INDEX(Raw_D3!$H$2:$H$1001,$AR7),""))) -> 6 | I7: =IF($A7="","",IF($AP7<>"",INDEX(Raw_D1!$I$2:$I$1001,$AP7),IF($AR7<>"",INDEX(Raw_D3!$I$2:$I$1001,$AR7),""))) -> 2 | J7: =IF($A7="","",IF($AP7<>"",INDEX(Raw_D1!$J$2:$J$1001,$AP7),IF($AR7<>"",INDEX(Raw_D3!$J$2:$J$1001,$AR7),""))) -> 0.24 | K7: =IF($A7="","",IF($AQ7<>"",IF(INDEX(Raw_D2!$C$2:$C$1001,$AQ7)="","",INDEX(Raw_D2!$C$2:$C$1001,$AQ7)),IF($AR7<>"",IF(INDEX(Raw_D3!$K$2:$K$1001,$AR7)="","",INDEX(Raw_D3!$K$2:$K$1001,$AR7)),""))) -> 0.2576 | L7: =IF($A7="","",IF($AQ7<>"",IF(INDEX(Raw_D2!$D$2:$D$1001,$AQ7)="","",INDEX(Raw_D2!$D$2:$D$1001,$AQ7)),IF($AR7<>"",IF(INDEX(Raw_D3!$L$2:$L$1001,$AR7)="","",INDEX(Raw_D3!$L$2:$L$1001,$AR7)),""))) -> 0.75 | M7: =IF($A7="","",IF($AQ7<>"",IF(INDEX(Raw_D2!$E$2:$E$1001,$AQ7)="","",INDEX(Raw_D2!$E$2:$E$1001,$AQ7)),IF($AR7<>"",IF(INDEX(Raw_D3!$M$2:$M$1001,$AR7)="","",INDEX(Raw_D3!$M$2:$M$1001,$AR7)),""))) -> 0.0896 | N7: =IF($A7="","",IF($AQ7<>"",IF(INDEX(Raw_D2!$F$2:$F$1001,$AQ7)="","",INDEX(Raw_D2!$F$2:$F$1001,$AQ7)),IF($AR7<>"",IF(INDEX(Raw_D3!$N$2:$N$1001,$AR7)="","",INDEX(Raw_D3!$N$2:$N$1001,$AR7)),""))) -> 0 | O7: =IF($A7="","",IF($AQ7<>"",IF(INDEX(Raw_D2!$G$2:$G$1001,$AQ7)="","",INDEX(Raw_D2!$G$2:$G$1001,$AQ7)),IF($AR7<>"",IF(INDEX(Raw_D3!$O$2:$O$1001,$AR7)="","",INDEX(Raw_D3!$O$2:$O$1001,$AR7)),""))) -> 1 | P7: =IF($A7="","",IF($AQ7<>"",IF(INDEX(Raw_D2!$H$2:$H$1001,$AQ7)="","",INDEX(Raw_D2!$H$2:$H$1001,$AQ7)),IF($AR7<>"",IF(INDEX(Raw_D3!$P$2:$P$1001,$AR7)="","",INDEX(Raw_D3!$P$2:$P$1001,$AR7)),""))) -> 1 | Q7: =IF($A7="","",IF(AND($AP7<>"",$AQ7<>""),"D1+D2",IF($AR7<>"","D3","Incomplete"))) -> D1+D2 | R7: =IF($A7="","",IF($K7="",IF($J7="","",ROUND(Lookups!$K$5+Lookups!$K$4*$J7,4)),$K7)) -> 0.2576 | S7: =IF($A7="","",IF($K7="","Imputed","Original")) -> Original | T7: =IF($A7="","",IF($P7="","Missing",IF($P7=$N7+$O7,"OK","Mismatch"))) -> OK | U7: =IF($A7="","",IF(COUNTIF($A$2:$A7,$A7)>1,"Duplicate","Unique")) -> Unique | V7: =IF($A7="","",IF(AND($U7="Unique",ISNUMBER($P7)),1,0)) -> 1 | W7: =IF($A7="","",IF(OR($H7=0,$H7=6),"Weekend","Weekday")) -> Weekend | X7: =IF($A7="","",TEXT($B7,"ddd")) -> Sat | Y7: =IF($A7="","",TEXT($B7,"mmm")) -> Jan | Z7: =IF($A7="","",IFERROR(VLOOKUP($C7,Lookups!$D$4:$E$7,2,FALSE),"Unknown")) -> Winter | AA7: =IF($A7="","",IFERROR(VLOOKUP($I7,Lookups!$A$4:$B$7,2,FALSE),"Unknown")) -> Mist/Cloudy | AB7: =IF($A7="","",TEXT($F7,"00")&":00") -> 05:00 | AC7: =IF($A7="","",VLOOKUP($F7,Lookups!$G$4:$H$8,2,TRUE)) -> Night (00-05) | AD7: =IF($A7="","",IF($J7="","",ROUND($J7*41,1))) -> 9.8 | AE7: =IF($A7="","",IF($R7="","",ROUND($R7*50,1))) -> 12.9 | AF7: =IF($A7="","",IF($L7="","",ROUND($L7*100,0))) -> 75 | AG7: =IF($A7="","",IF($M7="","",ROUND($M7*67,1))) -> 6 | AH7: =IF($A7="","",IF($P7="","",IF($P7=0,0,$O7/$P7))) -> 1 | AI7: =IF($A7="","",IF($P7="","",IF($P7>=Lookups!$K$7,"High",IF($P7<=Lookups!$K$8,"Low","Medium")))) -> Low | AJ7: =IF($A7="","",IF($AD7="","",IF($AD7<5,"Under 5 C",IF($AD7<10,"5-10 C",IF($AD7<15,"10-15 C","15 C and above"))))) -> 5-10 C | AK7: =IF($A7="","",IF($P7="","",$P7^2)) -> 1 | AL7: =IF($V7<>1,"",AVERAGEIFS(Clean_Data!$P$2:$P$1001,Clean_Data!$F$2:$F$1001,$F7,Clean_Data!$W$2:$W$1001,$W7,Clean_Data!$V$2:$V$1001,1)) -> 2.7 | AM7: =IF($V7<>1,"",IFERROR(($P7-$AL7)/SQRT(MAX(0,(SUMIFS(Clean_Data!$AK$2:$AK$1001,Clean_Data!$F$2:$F$1001,$F7,Clean_Data!$W$2:$W$1001,$W7,Clean_Data!$V$2:$V$1001,1)-COUNTIFS(Clean_Data!$F$2:$F$1001,$F7,Clean_Data!$W$2:$W$1001,$W7,Clean_Data!$V$2:$V$1001,1)*$AL7^2)/(COUNTIFS(Clean_Data!$F$2:$F$1001,$F7,Clean_Data!$W$2:$W$1001,$W7,Clean_Data!$V$2:$V$1001,1)-1))),"")) -> -0.65785918 | AN7: =IF($AM7="","",IF($AM7>=Lookups!$K$6,"High spike",IF($AM7<=-Lookups!$K$6,"Unusual low","Normal"))) -> Normal | AO7: =IF($V7<>1,"",$P7+ROW()/100000) -> 1.00007 | AP7: =IF($A7="","",IFERROR(MATCH($A7,Raw_D1!$A$2:$A$1001,0),"")) -> 6 | AQ7: =IF($A7="","",IFERROR(MATCH($A7,Raw_D2!$B$2:$B$1001,0),"")) -> 6 | AR7: =IF($A7="","",IFERROR(MATCH($A7,Raw_D3!$A$2:$A$1001,0),""))
A8: 7 | B8: =IF($A8="","",IF($AP8<>"",INDEX(Raw_D1!$B$2:$B$1001,$AP8),IF($AR8<>"",INDEX(Raw_D3!$B$2:$B$1001,$AR8),""))) -> 40544 | C8: =IF($A8="","",IF($AP8<>"",INDEX(Raw_D1!$C$2:$C$1001,$AP8),IF($AR8<>"",INDEX(Raw_D3!$C$2:$C$1001,$AR8),""))) -> 1 | D8: =IF($A8="","",IF($AP8<>"",INDEX(Raw_D1!$D$2:$D$1001,$AP8),IF($AR8<>"",INDEX(Raw_D3!$D$2:$D$1001,$AR8),""))) -> 0 | E8: =IF($A8="","",IF($AP8<>"",INDEX(Raw_D1!$E$2:$E$1001,$AP8),IF($AR8<>"",INDEX(Raw_D3!$E$2:$E$1001,$AR8),""))) -> 1 | F8: =IF($A8="","",IF($AP8<>"",INDEX(Raw_D1!$F$2:$F$1001,$AP8),IF($AR8<>"",INDEX(Raw_D3!$F$2:$F$1001,$AR8),""))) -> 6 | G8: =IF($A8="","",IF($AP8<>"",IF(INDEX(Raw_D1!$G$2:$G$1001,$AP8),1,0),IF($AR8<>"",IF(INDEX(Raw_D3!$G$2:$G$1001,$AR8),1,0),""))) -> 0 | H8: =IF($A8="","",IF($AP8<>"",INDEX(Raw_D1!$H$2:$H$1001,$AP8),IF($AR8<>"",INDEX(Raw_D3!$H$2:$H$1001,$AR8),""))) -> 6 | I8: =IF($A8="","",IF($AP8<>"",INDEX(Raw_D1!$I$2:$I$1001,$AP8),IF($AR8<>"",INDEX(Raw_D3!$I$2:$I$1001,$AR8),""))) -> 1 | J8: =IF($A8="","",IF($AP8<>"",INDEX(Raw_D1!$J$2:$J$1001,$AP8),IF($AR8<>"",INDEX(Raw_D3!$J$2:$J$1001,$AR8),""))) -> 0.22 | K8: =IF($A8="","",IF($AQ8<>"",IF(INDEX(Raw_D2!$C$2:$C$1001,$AQ8)="","",INDEX(Raw_D2!$C$2:$C$1001,$AQ8)),IF($AR8<>"",IF(INDEX(Raw_D3!$K$2:$K$1001,$AR8)="","",INDEX(Raw_D3!$K$2:$K$1001,$AR8)),""))) -> 0.2727 | L8: =IF($A8="","",IF($AQ8<>"",IF(INDEX(Raw_D2!$D$2:$D$1001,$AQ8)="","",INDEX(Raw_D2!$D$2:$D$1001,$AQ8)),IF($AR8<>"",IF(INDEX(Raw_D3!$L$2:$L$1001,$AR8)="","",INDEX(Raw_D3!$L$2:$L$1001,$AR8)),""))) -> 0.8 | M8: =IF($A8="","",IF($AQ8<>"",IF(INDEX(Raw_D2!$E$2:$E$1001,$AQ8)="","",INDEX(Raw_D2!$E$2:$E$1001,$AQ8)),IF($AR8<>"",IF(INDEX(Raw_D3!$M$2:$M$1001,$AR8)="","",INDEX(Raw_D3!$M$2:$M$1001,$AR8)),""))) -> 0 | N8: =IF($A8="","",IF($AQ8<>"",IF(INDEX(Raw_D2!$F$2:$F$1001,$AQ8)="","",INDEX(Raw_D2!$F$2:$F$1001,$AQ8)),IF($AR8<>"",IF(INDEX(Raw_D3!$N$2:$N$1001,$AR8)="","",INDEX(Raw_D3!$N$2:$N$1001,$AR8)),""))) -> 2 | O8: =IF($A8="","",IF($AQ8<>"",IF(INDEX(Raw_D2!$G$2:$G$1001,$AQ8)="","",INDEX(Raw_D2!$G$2:$G$1001,$AQ8)),IF($AR8<>"",IF(INDEX(Raw_D3!$O$2:$O$1001,$AR8)="","",INDEX(Raw_D3!$O$2:$O$1001,$AR8)),""))) -> 0 | P8: =IF($A8="","",IF($AQ8<>"",IF(INDEX(Raw_D2!$H$2:$H$1001,$AQ8)="","",INDEX(Raw_D2!$H$2:$H$1001,$AQ8)),IF($AR8<>"",IF(INDEX(Raw_D3!$P$2:$P$1001,$AR8)="","",INDEX(Raw_D3!$P$2:$P$1001,$AR8)),""))) -> 2 | Q8: =IF($A8="","",IF(AND($AP8<>"",$AQ8<>""),"D1+D2",IF($AR8<>"","D3","Incomplete"))) -> D1+D2 | R8: =IF($A8="","",IF($K8="",IF($J8="","",ROUND(Lookups!$K$5+Lookups!$K$4*$J8,4)),$K8)) -> 0.2727 | S8: =IF($A8="","",IF($K8="","Imputed","Original")) -> Original | T8: =IF($A8="","",IF($P8="","Missing",IF($P8=$N8+$O8,"OK","Mismatch"))) -> OK | U8: =IF($A8="","",IF(COUNTIF($A$2:$A8,$A8)>1,"Duplicate","Unique")) -> Unique | V8: =IF($A8="","",IF(AND($U8="Unique",ISNUMBER($P8)),1,0)) -> 1 | W8: =IF($A8="","",IF(OR($H8=0,$H8=6),"Weekend","Weekday")) -> Weekend | X8: =IF($A8="","",TEXT($B8,"ddd")) -> Sat | Y8: =IF($A8="","",TEXT($B8,"mmm")) -> Jan | Z8: =IF($A8="","",IFERROR(VLOOKUP($C8,Lookups!$D$4:$E$7,2,FALSE),"Unknown")) -> Winter | AA8: =IF($A8="","",IFERROR(VLOOKUP($I8,Lookups!$A$4:$B$7,2,FALSE),"Unknown")) -> Clear | AB8: =IF($A8="","",TEXT($F8,"00")&":00") -> 06:00 | AC8: =IF($A8="","",VLOOKUP($F8,Lookups!$G$4:$H$8,2,TRUE)) -> Morning Peak (06-09) | AD8: =IF($A8="","",IF($J8="","",ROUND($J8*41,1))) -> 9 | AE8: =IF($A8="","",IF($R8="","",ROUND($R8*50,1))) -> 13.6 | AF8: =IF($A8="","",IF($L8="","",ROUND($L8*100,0))) -> 80 | AG8: =IF($A8="","",IF($M8="","",ROUND($M8*67,1))) -> 0 | AH8: =IF($A8="","",IF($P8="","",IF($P8=0,0,$O8/$P8))) -> 0 | AI8: =IF($A8="","",IF($P8="","",IF($P8>=Lookups!$K$7,"High",IF($P8<=Lookups!$K$8,"Low","Medium")))) -> Low | AJ8: =IF($A8="","",IF($AD8="","",IF($AD8<5,"Under 5 C",IF($AD8<10,"5-10 C",IF($AD8<15,"10-15 C","15 C and above"))))) -> 5-10 C | AK8: =IF($A8="","",IF($P8="","",$P8^2)) -> 4 | AL8: =IF($V8<>1,"",AVERAGEIFS(Clean_Data!$P$2:$P$1001,Clean_Data!$F$2:$F$1001,$F8,Clean_Data!$W$2:$W$1001,$W8,Clean_Data!$V$2:$V$1001,1)) -> 2.1538462 | AM8: =IF($V8<>1,"",IFERROR(($P8-$AL8)/SQRT(MAX(0,(SUMIFS(Clean_Data!$AK$2:$AK$1001,Clean_Data!$F$2:$F$1001,$F8,Clean_Data!$W$2:$W$1001,$W8,Clean_Data!$V$2:$V$1001,1)-COUNTIFS(Clean_Data!$F$2:$F$1001,$F8,Clean_Data!$W$2:$W$1001,$W8,Clean_Data!$V$2:$V$1001,1)*$AL8^2)/(COUNTIFS(Clean_Data!$F$2:$F$1001,$F8,Clean_Data!$W$2:$W$1001,$W8,Clean_Data!$V$2:$V$1001,1)-1))),"")) -> -0.12670245 | AN8: =IF($AM8="","",IF($AM8>=Lookups!$K$6,"High spike",IF($AM8<=-Lookups!$K$6,"Unusual low","Normal"))) -> Normal | AO8: =IF($V8<>1,"",$P8+ROW()/100000) -> 2.00008 | AP8: =IF($A8="","",IFERROR(MATCH($A8,Raw_D1!$A$2:$A$1001,0),"")) -> 7 | AQ8: =IF($A8="","",IFERROR(MATCH($A8,Raw_D2!$B$2:$B$1001,0),"")) -> 7 | AR8: =IF($A8="","",IFERROR(MATCH($A8,Raw_D3!$A$2:$A$1001,0),""))
A9: 8 | B9: =IF($A9="","",IF($AP9<>"",INDEX(Raw_D1!$B$2:$B$1001,$AP9),IF($AR9<>"",INDEX(Raw_D3!$B$2:$B$1001,$AR9),""))) -> 40544 | C9: =IF($A9="","",IF($AP9<>"",INDEX(Raw_D1!$C$2:$C$1001,$AP9),IF($AR9<>"",INDEX(Raw_D3!$C$2:$C$1001,$AR9),""))) -> 1 | D9: =IF($A9="","",IF($AP9<>"",INDEX(Raw_D1!$D$2:$D$1001,$AP9),IF($AR9<>"",INDEX(Raw_D3!$D$2:$D$1001,$AR9),""))) -> 0 | E9: =IF($A9="","",IF($AP9<>"",INDEX(Raw_D1!$E$2:$E$1001,$AP9),IF($AR9<>"",INDEX(Raw_D3!$E$2:$E$1001,$AR9),""))) -> 1 | F9: =IF($A9="","",IF($AP9<>"",INDEX(Raw_D1!$F$2:$F$1001,$AP9),IF($AR9<>"",INDEX(Raw_D3!$F$2:$F$1001,$AR9),""))) -> 7 | G9: =IF($A9="","",IF($AP9<>"",IF(INDEX(Raw_D1!$G$2:$G$1001,$AP9),1,0),IF($AR9<>"",IF(INDEX(Raw_D3!$G$2:$G$1001,$AR9),1,0),""))) -> 0 | H9: =IF($A9="","",IF($AP9<>"",INDEX(Raw_D1!$H$2:$H$1001,$AP9),IF($AR9<>"",INDEX(Raw_D3!$H$2:$H$1001,$AR9),""))) -> 6 | I9: =IF($A9="","",IF($AP9<>"",INDEX(Raw_D1!$I$2:$I$1001,$AP9),IF($AR9<>"",INDEX(Raw_D3!$I$2:$I$1001,$AR9),""))) -> 1 | J9: =IF($A9="","",IF($AP9<>"",INDEX(Raw_D1!$J$2:$J$1001,$AP9),IF($AR9<>"",INDEX(Raw_D3!$J$2:$J$1001,$AR9),""))) -> 0.2 | K9: =IF($A9="","",IF($AQ9<>"",IF(INDEX(Raw_D2!$C$2:$C$1001,$AQ9)="","",INDEX(Raw_D2!$C$2:$C$1001,$AQ9)),IF($AR9<>"",IF(INDEX(Raw_D3!$K$2:$K$1001,$AR9)="","",INDEX(Raw_D3!$K$2:$K$1001,$AR9)),""))) -> 0.2576 | L9: =IF($A9="","",IF($AQ9<>"",IF(INDEX(Raw_D2!$D$2:$D$1001,$AQ9)="","",INDEX(Raw_D2!$D$2:$D$1001,$AQ9)),IF($AR9<>"",IF(INDEX(Raw_D3!$L$2:$L$1001,$AR9)="","",INDEX(Raw_D3!$L$2:$L$1001,$AR9)),""))) -> 0.86 | M9: =IF($A9="","",IF($AQ9<>"",IF(INDEX(Raw_D2!$E$2:$E$1001,$AQ9)="","",INDEX(Raw_D2!$E$2:$E$1001,$AQ9)),IF($AR9<>"",IF(INDEX(Raw_D3!$M$2:$M$1001,$AR9)="","",INDEX(Raw_D3!$M$2:$M$1001,$AR9)),""))) -> 0 | N9: =IF($A9="","",IF($AQ9<>"",IF(INDEX(Raw_D2!$F$2:$F$1001,$AQ9)="","",INDEX(Raw_D2!$F$2:$F$1001,$AQ9)),IF($AR9<>"",IF(INDEX(Raw_D3!$N$2:$N$1001,$AR9)="","",INDEX(Raw_D3!$N$2:$N$1001,$AR9)),""))) -> 1 | O9: =IF($A9="","",IF($AQ9<>"",IF(INDEX(Raw_D2!$G$2:$G$1001,$AQ9)="","",INDEX(Raw_D2!$G$2:$G$1001,$AQ9)),IF($AR9<>"",IF(INDEX(Raw_D3!$O$2:$O$1001,$AR9)="","",INDEX(Raw_D3!$O$2:$O$1001,$AR9)),""))) -> 2 | P9: =IF($A9="","",IF($AQ9<>"",IF(INDEX(Raw_D2!$H$2:$H$1001,$AQ9)="","",INDEX(Raw_D2!$H$2:$H$1001,$AQ9)),IF($AR9<>"",IF(INDEX(Raw_D3!$P$2:$P$1001,$AR9)="","",INDEX(Raw_D3!$P$2:$P$1001,$AR9)),""))) -> 3 | Q9: =IF($A9="","",IF(AND($AP9<>"",$AQ9<>""),"D1+D2",IF($AR9<>"","D3","Incomplete"))) -> D1+D2 | R9: =IF($A9="","",IF($K9="",IF($J9="","",ROUND(Lookups!$K$5+Lookups!$K$4*$J9,4)),$K9)) -> 0.2576 | S9: =IF($A9="","",IF($K9="","Imputed","Original")) -> Original | T9: =IF($A9="","",IF($P9="","Missing",IF($P9=$N9+$O9,"OK","Mismatch"))) -> OK | U9: =IF($A9="","",IF(COUNTIF($A$2:$A9,$A9)>1,"Duplicate","Unique")) -> Unique | V9: =IF($A9="","",IF(AND($U9="Unique",ISNUMBER($P9)),1,0)) -> 1 | W9: =IF($A9="","",IF(OR($H9=0,$H9=6),"Weekend","Weekday")) -> Weekend | X9: =IF($A9="","",TEXT($B9,"ddd")) -> Sat | Y9: =IF($A9="","",TEXT($B9,"mmm")) -> Jan | Z9: =IF($A9="","",IFERROR(VLOOKUP($C9,Lookups!$D$4:$E$7,2,FALSE),"Unknown")) -> Winter | AA9: =IF($A9="","",IFERROR(VLOOKUP($I9,Lookups!$A$4:$B$7,2,FALSE),"Unknown")) -> Clear | AB9: =IF($A9="","",TEXT($F9,"00")&":00") -> 07:00 | AC9: =IF($A9="","",VLOOKUP($F9,Lookups!$G$4:$H$8,2,TRUE)) -> Morning Peak (06-09) | AD9: =IF($A9="","",IF($J9="","",ROUND($J9*41,1))) -> 8.2 | AE9: =IF($A9="","",IF($R9="","",ROUND($R9*50,1))) -> 12.9 | AF9: =IF($A9="","",IF($L9="","",ROUND($L9*100,0))) -> 86 | AG9: =IF($A9="","",IF($M9="","",ROUND($M9*67,1))) -> 0 | AH9: =IF($A9="","",IF($P9="","",IF($P9=0,0,$O9/$P9))) -> 0.66666667 | AI9: =IF($A9="","",IF($P9="","",IF($P9>=Lookups!$K$7,"High",IF($P9<=Lookups!$K$8,"Low","Medium")))) -> Low | AJ9: =IF($A9="","",IF($AD9="","",IF($AD9<5,"Under 5 C",IF($AD9<10,"5-10 C",IF($AD9<15,"10-15 C","15 C and above"))))) -> 5-10 C | AK9: =IF($A9="","",IF($P9="","",$P9^2)) -> 9 | AL9: =IF($V9<>1,"",AVERAGEIFS(Clean_Data!$P$2:$P$1001,Clean_Data!$F$2:$F$1001,$F9,Clean_Data!$W$2:$W$1001,$W9,Clean_Data!$V$2:$V$1001,1)) -> 5.4285714 | AM9: =IF($V9<>1,"",IFERROR(($P9-$AL9)/SQRT(MAX(0,(SUMIFS(Clean_Data!$AK$2:$AK$1001,Clean_Data!$F$2:$F$1001,$F9,Clean_Data!$W$2:$W$1001,$W9,Clean_Data!$V$2:$V$1001,1)-COUNTIFS(Clean_Data!$F$2:$F$1001,$F9,Clean_Data!$W$2:$W$1001,$W9,Clean_Data!$V$2:$V$1001,1)*$AL9^2)/(COUNTIFS(Clean_Data!$F$2:$F$1001,$F9,Clean_Data!$W$2:$W$1001,$W9,Clean_Data!$V$2:$V$1001,1)-1))),"")) -> -0.75243226 | AN9: =IF($AM9="","",IF($AM9>=Lookups!$K$6,"High spike",IF($AM9<=-Lookups!$K$6,"Unusual low","Normal"))) -> Normal | AO9: =IF($V9<>1,"",$P9+ROW()/100000) -> 3.00009 | AP9: =IF($A9="","",IFERROR(MATCH($A9,Raw_D1!$A$2:$A$1001,0),"")) -> 8 | AQ9: =IF($A9="","",IFERROR(MATCH($A9,Raw_D2!$B$2:$B$1001,0),"")) -> 8 | AR9: =IF($A9="","",IFERROR(MATCH($A9,Raw_D3!$A$2:$A$1001,0),""))
A10: 9 | B10: =IF($A10="","",IF($AP10<>"",INDEX(Raw_D1!$B$2:$B$1001,$AP10),IF($AR10<>"",INDEX(Raw_D3!$B$2:$B$1001,$AR10),""))) -> 40544 | C10: =IF($A10="","",IF($AP10<>"",INDEX(Raw_D1!$C$2:$C$1001,$AP10),IF($AR10<>"",INDEX(Raw_D3!$C$2:$C$1001,$AR10),""))) -> 1 | D10: =IF($A10="","",IF($AP10<>"",INDEX(Raw_D1!$D$2:$D$1001,$AP10),IF($AR10<>"",INDEX(Raw_D3!$D$2:$D$1001,$AR10),""))) -> 0 | E10: =IF($A10="","",IF($AP10<>"",INDEX(Raw_D1!$E$2:$E$1001,$AP10),IF($AR10<>"",INDEX(Raw_D3!$E$2:$E$1001,$AR10),""))) -> 1 | F10: =IF($A10="","",IF($AP10<>"",INDEX(Raw_D1!$F$2:$F$1001,$AP10),IF($AR10<>"",INDEX(Raw_D3!$F$2:$F$1001,$AR10),""))) -> 8 | G10: =IF($A10="","",IF($AP10<>"",IF(INDEX(Raw_D1!$G$2:$G$1001,$AP10),1,0),IF($AR10<>"",IF(INDEX(Raw_D3!$G$2:$G$1001,$AR10),1,0),""))) -> 0 | H10: =IF($A10="","",IF($AP10<>"",INDEX(Raw_D1!$H$2:$H$1001,$AP10),IF($AR10<>"",INDEX(Raw_D3!$H$2:$H$1001,$AR10),""))) -> 6 | I10: =IF($A10="","",IF($AP10<>"",INDEX(Raw_D1!$I$2:$I$1001,$AP10),IF($AR10<>"",INDEX(Raw_D3!$I$2:$I$1001,$AR10),""))) -> 1 | J10: =IF($A10="","",IF($AP10<>"",INDEX(Raw_D1!$J$2:$J$1001,$AP10),IF($AR10<>"",INDEX(Raw_D3!$J$2:$J$1001,$AR10),""))) -> 0.24 | K10: =IF($A10="","",IF($AQ10<>"",IF(INDEX(Raw_D2!$C$2:$C$1001,$AQ10)="","",INDEX(Raw_D2!$C$2:$C$1001,$AQ10)),IF($AR10<>"",IF(INDEX(Raw_D3!$K$2:$K$1001,$AR10)="","",INDEX(Raw_D3!$K$2:$K$1001,$AR10)),""))) | L10: =IF($A10="","",IF($AQ10<>"",IF(INDEX(Raw_D2!$D$2:$D$1001,$AQ10)="","",INDEX(Raw_D2!$D$2:$D$1001,$AQ10)),IF($AR10<>"",IF(INDEX(Raw_D3!$L$2:$L$1001,$AR10)="","",INDEX(Raw_D3!$L$2:$L$1001,$AR10)),""))) -> 0.75 | M10: =IF($A10="","",IF($AQ10<>"",IF(INDEX(Raw_D2!$E$2:$E$1001,$AQ10)="","",INDEX(Raw_D2!$E$2:$E$1001,$AQ10)),IF($AR10<>"",IF(INDEX(Raw_D3!$M$2:$M$1001,$AR10)="","",INDEX(Raw_D3!$M$2:$M$1001,$AR10)),""))) -> 0 | N10: =IF($A10="","",IF($AQ10<>"",IF(INDEX(Raw_D2!$F$2:$F$1001,$AQ10)="","",INDEX(Raw_D2!$F$2:$F$1001,$AQ10)),IF($AR10<>"",IF(INDEX(Raw_D3!$N$2:$N$1001,$AR10)="","",INDEX(Raw_D3!$N$2:$N$1001,$AR10)),""))) -> 1 | O10: =IF($A10="","",IF($AQ10<>"",IF(INDEX(Raw_D2!$G$2:$G$1001,$AQ10)="","",INDEX(Raw_D2!$G$2:$G$1001,$AQ10)),IF($AR10<>"",IF(INDEX(Raw_D3!$O$2:$O$1001,$AR10)="","",INDEX(Raw_D3!$O$2:$O$1001,$AR10)),""))) -> 7 | P10: =IF($A10="","",IF($AQ10<>"",IF(INDEX(Raw_D2!$H$2:$H$1001,$AQ10)="","",INDEX(Raw_D2!$H$2:$H$1001,$AQ10)),IF($AR10<>"",IF(INDEX(Raw_D3!$P$2:$P$1001,$AR10)="","",INDEX(Raw_D3!$P$2:$P$1001,$AR10)),""))) -> 8 | Q10: =IF($A10="","",IF(AND($AP10<>"",$AQ10<>""),"D1+D2",IF($AR10<>"","D3","Incomplete"))) -> D1+D2 | R10: =IF($A10="","",IF($K10="",IF($J10="","",ROUND(Lookups!$K$5+Lookups!$K$4*$J10,4)),$K10)) -> 0.2444 | S10: =IF($A10="","",IF($K10="","Imputed","Original")) -> Imputed | T10: =IF($A10="","",IF($P10="","Missing",IF($P10=$N10+$O10,"OK","Mismatch"))) -> OK | U10: =IF($A10="","",IF(COUNTIF($A$2:$A10,$A10)>1,"Duplicate","Unique")) -> Unique | V10: =IF($A10="","",IF(AND($U10="Unique",ISNUMBER($P10)),1,0)) -> 1 | W10: =IF($A10="","",IF(OR($H10=0,$H10=6),"Weekend","Weekday")) -> Weekend | X10: =IF($A10="","",TEXT($B10,"ddd")) -> Sat | Y10: =IF($A10="","",TEXT($B10,"mmm")) -> Jan | Z10: =IF($A10="","",IFERROR(VLOOKUP($C10,Lookups!$D$4:$E$7,2,FALSE),"Unknown")) -> Winter | AA10: =IF($A10="","",IFERROR(VLOOKUP($I10,Lookups!$A$4:$B$7,2,FALSE),"Unknown")) -> Clear | AB10: =IF($A10="","",TEXT($F10,"00")&":00") -> 08:00 | AC10: =IF($A10="","",VLOOKUP($F10,Lookups!$G$4:$H$8,2,TRUE)) -> Morning Peak (06-09) | AD10: =IF($A10="","",IF($J10="","",ROUND($J10*41,1))) -> 9.8 | AE10: =IF($A10="","",IF($R10="","",ROUND($R10*50,1))) -> 12.2 | AF10: =IF($A10="","",IF($L10="","",ROUND($L10*100,0))) -> 75 | AG10: =IF($A10="","",IF($M10="","",ROUND($M10*67,1))) -> 0 | AH10: =IF($A10="","",IF($P10="","",IF($P10=0,0,$O10/$P10))) -> 0.875 | AI10: =IF($A10="","",IF($P10="","",IF($P10>=Lookups!$K$7,"High",IF($P10<=Lookups!$K$8,"Low","Medium")))) -> Low | AJ10: =IF($A10="","",IF($AD10="","",IF($AD10<5,"Under 5 C",IF($AD10<10,"5-10 C",IF($AD10<15,"10-15 C","15 C and above"))))) -> 5-10 C | AK10: =IF($A10="","",IF($P10="","",$P10^2)) -> 64 | AL10: =IF($V10<>1,"",AVERAGEIFS(Clean_Data!$P$2:$P$1001,Clean_Data!$F$2:$F$1001,$F10,Clean_Data!$W$2:$W$1001,$W10,Clean_Data!$V$2:$V$1001,1)) -> 17.785714 | AM10: =IF($V10<>1,"",IFERROR(($P10-$AL10)/SQRT(MAX(0,(SUMIFS(Clean_Data!$AK$2:$AK$1001,Clean_Data!$F$2:$F$1001,$F10,Clean_Data!$W$2:$W$1001,$W10,Clean_Data!$V$2:$V$1001,1)-COUNTIFS(Clean_Data!$F$2:$F$1001,$F10,Clean_Data!$W$2:$W$1001,$W10,Clean_Data!$V$2:$V$1001,1)*$AL10^2)/(COUNTIFS(Clean_Data!$F$2:$F$1001,$F10,Clean_Data!$W$2:$W$1001,$W10,Clean_Data!$V$2:$V$1001,1)-1))),"")) -> -1.1505826 | AN10: =IF($AM10="","",IF($AM10>=Lookups!$K$6,"High spike",IF($AM10<=-Lookups!$K$6,"Unusual low","Normal"))) -> Normal | AO10: =IF($V10<>1,"",$P10+ROW()/100000) -> 8.0001 | AP10: =IF($A10="","",IFERROR(MATCH($A10,Raw_D1!$A$2:$A$1001,0),"")) -> 9 | AQ10: =IF($A10="","",IFERROR(MATCH($A10,Raw_D2!$B$2:$B$1001,0),"")) -> 9 | AR10: =IF($A10="","",IFERROR(MATCH($A10,Raw_D3!$A$2:$A$1001,0),""))
